<?xml version='1.0' encoding='utf-8'?>
<mujoco model="fr5_rh56e2_scene">
  <compiler angle="radian" />
  <asset>
    <mesh name="meshes__fr5v6__visual__base_link" content_type="model/obj" file="meshes__fr5v6__visual__base_link.obj" />
    <mesh name="meshes__fr5v6__visual__j1_link" content_type="model/obj" file="meshes__fr5v6__visual__j1_link.obj" />
    <mesh name="meshes__fr5v6__visual__j2_link" content_type="model/obj" file="meshes__fr5v6__visual__j2_link.obj" />
    <mesh name="meshes__fr5v6__visual__j3_link" content_type="model/obj" file="meshes__fr5v6__visual__j3_link.obj" />
    <mesh name="meshes__fr5v6__visual__j4_link" content_type="model/obj" file="meshes__fr5v6__visual__j4_link.obj" />
    <mesh name="meshes__fr5v6__visual__j5_link" content_type="model/obj" file="meshes__fr5v6__visual__j5_link.obj" />
    <mesh name="meshes__fr5v6__visual__j6_link" content_type="model/obj" file="meshes__fr5v6__visual__j6_link.obj" />
    <mesh name="meshes__base_link" content_type="model/stl" file="meshes__base_link.stl" />
    <mesh name="meshes__right_plam_1" content_type="model/stl" file="meshes__right_plam_1.stl" />
    <mesh name="meshes__right_plam_2" content_type="model/stl" file="meshes__right_plam_2.stl" />
    <mesh name="meshes__right_plam_force_sensor" content_type="model/stl" file="meshes__right_plam_force_sensor.stl" />
    <mesh name="meshes__right_thumb_1" content_type="model/stl" file="meshes__right_thumb_1.stl" />
    <mesh name="meshes__right_thumb_2" content_type="model/stl" file="meshes__right_thumb_2.stl" />
    <mesh name="meshes__right_thumb_3" content_type="model/stl" file="meshes__right_thumb_3.stl" />
    <mesh name="meshes__right_thumb_force_sensor_2" content_type="model/stl" file="meshes__right_thumb_force_sensor_2.stl" />
    <mesh name="meshes__right_thumb_4" content_type="model/stl" file="meshes__right_thumb_4.stl" />
    <mesh name="meshes__right_thumb_force_sensor_3" content_type="model/stl" file="meshes__right_thumb_force_sensor_3.stl" />
    <mesh name="meshes__right_thumb_force_sensor_4" content_type="model/stl" file="meshes__right_thumb_force_sensor_4.stl" />
    <mesh name="meshes__right_thumb_force_sensor_1" content_type="model/stl" file="meshes__right_thumb_force_sensor_1.stl" />
    <mesh name="meshes__right_index_1" content_type="model/stl" file="meshes__right_index_1.stl" />
    <mesh name="meshes__right_index_2" content_type="model/stl" file="meshes__right_index_2.stl" />
    <mesh name="meshes__right_index_force_sensor_2" content_type="model/stl" file="meshes__right_index_force_sensor_2.stl" />
    <mesh name="meshes__right_index_force_sensor_3" content_type="model/stl" file="meshes__right_index_force_sensor_3.stl" />
    <mesh name="meshes__right_index_force_sensor_1" content_type="model/stl" file="meshes__right_index_force_sensor_1.stl" />
    <mesh name="meshes__right_middle_1" content_type="model/stl" file="meshes__right_middle_1.stl" />
    <mesh name="meshes__right_middle_2" content_type="model/stl" file="meshes__right_middle_2.stl" />
    <mesh name="meshes__right_middle_force_sensor_2" content_type="model/stl" file="meshes__right_middle_force_sensor_2.stl" />
    <mesh name="meshes__right_middle_force_sensor_3" content_type="model/stl" file="meshes__right_middle_force_sensor_3.stl" />
    <mesh name="meshes__right_middle_force_sensor_1" content_type="model/stl" file="meshes__right_middle_force_sensor_1.stl" />
    <mesh name="meshes__right_ring_1" content_type="model/stl" file="meshes__right_ring_1.stl" />
    <mesh name="meshes__right_ring_2" content_type="model/stl" file="meshes__right_ring_2.stl" />
    <mesh name="meshes__right_ring_force_sensor_2" content_type="model/stl" file="meshes__right_ring_force_sensor_2.stl" />
    <mesh name="meshes__right_ring_force_sensor_3" content_type="model/stl" file="meshes__right_ring_force_sensor_3.stl" />
    <mesh name="meshes__right_ring_force_sensor_1" content_type="model/stl" file="meshes__right_ring_force_sensor_1.stl" />
    <mesh name="meshes__right_little_1" content_type="model/stl" file="meshes__right_little_1.stl" />
    <mesh name="meshes__right_little_2" content_type="model/stl" file="meshes__right_little_2.stl" />
    <mesh name="meshes__right_little_force_sensor_2" content_type="model/stl" file="meshes__right_little_force_sensor_2.stl" />
    <mesh name="meshes__right_little_force_sensor_3" content_type="model/stl" file="meshes__right_little_force_sensor_3.stl" />
    <mesh name="meshes__right_little_force_sensor_1" content_type="model/stl" file="meshes__right_little_force_sensor_1.stl" />
  </asset>
  <worldbody>
    <geom pos="0.55 0 0.52" quat="1 0 0 0" type="mesh" rgba="0.89804 0.91765 0.92941 1" mesh="meshes__fr5v6__visual__base_link" />
    <body name="j1_Link" pos="0.55 0 0.52">
      <inertial pos="5.0029e-07 -0.0040922 0.14629" quat="0.999588 0.0287044 7.54149e-06 -1.58789e-05" mass="4.3771" diaginertia="0.010731 0.0104154 0.00817191" />
      <joint name="j1" pos="0 0 0" axis="0 0 1" range="-3.0543 3.0543" actuatorfrcrange="-150 150" />
      <geom type="mesh" rgba="0.89804 0.91765 0.92941 1" mesh="meshes__fr5v6__visual__j1_link" />
      <body name="j2_Link" pos="0 0 0.152" quat="0.707105 0.707108 0 0">
        <inertial pos="-0.2125 -5.7643e-09 0.1346" quat="0.5 0.5 0.5 0.5" mass="14.458" diaginertia="0.4559 0.44974 0.028392" />
        <joint name="j2" pos="0 0 0" axis="0 0 1" range="-4.6251 1.4835" actuatorfrcrange="-150 150" />
        <geom type="mesh" rgba="0.89804 0.91765 0.92941 1" mesh="meshes__fr5v6__visual__j2_link" />
        <body name="j3_Link" pos="-0.425 0 0">
          <inertial pos="-0.18793 -8.4503e-07 0.0066357" quat="0.510607 0.489172 0.489196 0.510568" mass="7.6737" diaginertia="0.16971 0.168834 0.00821541" />
          <joint name="j3" pos="0 0 0" axis="0 0 1" range="-2.8274 2.8274" actuatorfrcrange="-150 150" />
          <geom type="mesh" rgba="0.89804 0.91765 0.92941 1" mesh="meshes__fr5v6__visual__j3_link" />
          <body name="j4_Link" pos="-0.39501 0 0">
            <inertial pos="4.98e-07 -0.003754 0.097155" quat="0.736149 0.676819 -6.33095e-05 7.15237e-05" mass="1.6266" diaginertia="0.00216 0.00199337 0.00154233" />
            <joint name="j4" pos="0 0 0" axis="0 0 1" range="-4.6251 1.4835" actuatorfrcrange="-28 28" />
            <geom type="mesh" rgba="0.89804 0.91765 0.92941 1" mesh="meshes__fr5v6__visual__j4_link" />
            <body name="j5_Link" pos="0 0 0.1021" quat="0.707105 0.707108 0 0">
              <inertial pos="-4.5588e-07 0.0038617 0.098257" quat="0.68712 0.726544 0.000128667 -0.000114125" mass="1.5812" diaginertia="0.0020612 0.00195889 0.00144611" />
              <joint name="j5" pos="0 0 0" axis="0 0 1" range="-3.0543 3.0543" actuatorfrcrange="-28 28" />
              <geom type="mesh" rgba="0.89804 0.91765 0.92941 1" mesh="meshes__fr5v6__visual__j5_link" />
              <body name="j6_Link" pos="0 0 0.102" quat="0.707105 -0.707108 0 0">
                <inertial pos="-0.00706182 -0.0120964 0.119881" quat="0.989838 -0.0979298 -0.0712143 -0.0745644" mass="1.02215" diaginertia="0.00788102 0.00710895 0.0015185" />
                <joint name="j6" pos="0 0 0" axis="0 0 1" range="-3.0543 3.0543" actuatorfrcrange="-28 28" />
                <geom type="mesh" rgba="0.89804 0.91765 0.92941 1" mesh="meshes__fr5v6__visual__j6_link" />
                <geom pos="0 0 0.109013" quat="-1.64085e-08 0.707107 0.707107 -1.64085e-08" type="mesh" rgba="1 1 1 1" mesh="meshes__base_link" />
                <geom pos="1.41551e-09 0 0.139513" quat="-0.707107 -2.61376e-06 -2.61376e-06 -0.707107" type="mesh" rgba="0.25 0.25 0.25 1" mesh="meshes__right_plam_1" />
                <geom pos="1.41551e-09 0 0.139513" quat="-0.707107 -2.61376e-06 -2.61376e-06 -0.707107" type="mesh" rgba="1 1 1 1" mesh="meshes__right_plam_2" />
                <geom pos="-0.00036753 0.012296 0.228614" quat="3.90296e-06 -1.32455e-06 -0.707108 -0.707105" type="mesh" rgba="0.25 0.25 0.25 1" mesh="meshes__right_plam_force_sensor" />
                <body name="rh56e2_right_thumb_1" pos="-0.0269 0.02101 0.191613" quat="0.707107 -2.58094e-06 -2.58094e-06 0.707107">
                  <inertial pos="0.00067 0.00494 -0.00671" quat="0.640735 0.761552 -0.0798523 -0.0558616" mass="0.01537" diaginertia="9.91429e-07 8.69962e-07 6.55049e-07" />
                  <joint name="rh56e2_right_thumb_1_joint" pos="0 0 0" axis="0 0 -1" range="0 1.658" actuatorfrcrange="-1 1" />
                  <geom type="mesh" rgba="1 1 1 1" mesh="meshes__right_thumb_1" />
                  <body name="rh56e2_right_thumb_2" pos="0.013438 0.012862 -0.0076" quat="0.499998 0.5 -0.500002 -0.5">
                    <inertial pos="-0.0330106 0.0134179 0.00535844" quat="0.0757838 0.603373 -0.260406 0.749924" mass="0.110574" diaginertia="4.33122e-05 3.98818e-05 1.33843e-05" />
                    <joint name="rh56e2_right_thumb_2_joint" pos="0 0 0" axis="0.17365 0 -0.984808" range="0 0.62" actuatorfrcrange="-1 1" />
                    <geom type="mesh" rgba="0.25 0.25 0.25 1" mesh="meshes__right_thumb_2" />
                    <geom pos="-0.023424 0.033251 0.007073" quat="0.639162 -0.398928 0.551278 0.358359" type="mesh" rgba="0.25 0.25 0.25 1" mesh="meshes__right_thumb_force_sensor_1" />
                    <body name="rh56e2_right_thumb_3" pos="-0.052954 0.032799 -0.0093372">
                      <inertial pos="-0.0111153 0.00147328 0.0113971" quat="0.692943 0.608412 0.382952 -0.0548777" mass="0.017909" diaginertia="3.37093e-06 3.33783e-06 2.42494e-06" />
                      <joint name="rh56e2_right_thumb_3_joint" pos="0 0 0" axis="0.17365 0 -0.984808" range="0 0.541052" actuatorfrcrange="-1 1" />
                      <geom type="mesh" rgba="0.25 0.25 0.25 1" mesh="meshes__right_thumb_3" />
                      <geom pos="-0.0080057 0.016443 0.0096921" quat="0.673514 -0.37233 0.560997 0.30501" type="mesh" rgba="0.25 0.25 0.25 1" mesh="meshes__right_thumb_force_sensor_2" />
                      <body name="rh56e2_right_thumb_4" pos="-0.01865 0.013373 -0.0022731">
                        <inertial pos="-0.0128424 0.00731961 0.0100428" quat="0.671895 0.699649 0.230737 -0.0762137" mass="0.00784659" diaginertia="1.33071e-06 1.21782e-06 6.26028e-07" />
                        <joint name="rh56e2_right_thumb_4_joint" pos="0 0 0" axis="0.17365 0 -0.984808" range="0 0.455531" actuatorfrcrange="-1 1" />
                        <geom type="mesh" rgba="0.25 0.25 0.25 1" mesh="meshes__right_thumb_4" />
                        <geom pos="-0.0076345 0.020486 0.0088067" quat="0.727041 -0.241283 0.610081 0.202473" type="mesh" rgba="0.25 0.25 0.25 1" mesh="meshes__right_thumb_force_sensor_3" />
                        <geom pos="-0.01883 0.027914 0.0068326" quat="0.490906 -0.588062 0.41181 0.493565" type="mesh" rgba="0.25 0.25 0.25 1" mesh="meshes__right_thumb_force_sensor_4" />
                      </body>
                    </body>
                  </body>
                </body>
                <body name="rh56e2_right_index_1" pos="-0.038679 0.000564671 0.265413" quat="0.508649 0.491198 0.491198 0.508649">
                  <inertial pos="0.00109257 0.0106015 0.00808668" quat="0.55995 0.462516 -0.532634 0.434554" mass="0.0188928" diaginertia="3.94835e-06 3.75686e-06 1.20374e-06" />
                  <joint name="rh56e2_right_index_1_joint" pos="0 0 0" axis="0 0 -1" range="0 1.4381" actuatorfrcrange="-1 1" />
                  <geom type="mesh" rgba="0.25 0.25 0.25 1" mesh="meshes__right_index_1" />
                  <geom pos="0.012046 0.019649 0.006651" quat="0.701686 -0.0622873 0.704358 0.0873853" type="mesh" rgba="0.25 0.25 0.25 1" mesh="meshes__right_index_force_sensor_1" />
                  <body name="rh56e2_right_index_2" pos="0.0034259 0.032596 0.00055">
                    <inertial pos="-0.000980626 0.0168026 0.00807178" quat="0.547952 0.365437 -0.596996 0.458041" mass="0.0113437" diaginertia="3.2034e-06 3.00377e-06 5.28116e-07" />
                    <joint name="rh56e2_right_index_2_joint" pos="0 0 0" axis="0 0 -1" range="0 1.47637" actuatorfrcrange="-1 1" />
                    <geom type="mesh" rgba="0.25 0.25 0.25 1" mesh="meshes__right_index_2" />
                    <geom pos="0.0081655 0.037446 0.0060795" quat="0.698536 0.13559 0.693985 -0.109758" type="mesh" rgba="0.25 0.25 0.25 1" mesh="meshes__right_index_force_sensor_2" />
                    <geom pos="0.0086237 0.052572 0.0060954" quat="0.658743 -0.226725 0.669773 0.257017" type="mesh" rgba="0.25 0.25 0.25 1" mesh="meshes__right_index_force_sensor_3" />
                  </body>
                </body>
                <body name="rh56e2_right_middle_1" pos="-0.0171 0.00056467 0.266013" quat="0.500001 0.499999 0.499999 0.500001">
                  <inertial pos="0.00114404 0.0108212 0.00809663" quat="0.558867 0.463915 -0.531422 0.435938" mass="0.0188628" diaginertia="3.94167e-06 3.75203e-06 1.20153e-06" />
                  <joint name="rh56e2_right_middle_1_joint" pos="0 0 0" axis="0 0 -1" range="0 1.4381" actuatorfrcrange="-1 1" />
                  <geom type="mesh" rgba="0.25 0.25 0.25 1" mesh="meshes__right_middle_1" />
                  <geom pos="0.012046 0.019649 0.006651" quat="0.703133 -0.0748445 0.703136 0.0748448" type="mesh" rgba="0.25 0.25 0.25 1" mesh="meshes__right_middle_force_sensor_1" />
                  <body name="rh56e2_right_middle_2" pos="0.0034259 0.032596 0.00055">
                    <inertial pos="0.00129017 0.022433 0.00807154" quat="0.561822 0.367162 -0.598502 0.437428" mass="0.0179991" diaginertia="6.09155e-06 5.86943e-06 8.51536e-07" />
                    <joint name="rh56e2_right_middle_2_joint" pos="0 0 0" axis="0 0 -1" range="0 1.47637" actuatorfrcrange="-1 1" />
                    <geom type="mesh" rgba="0.25 0.25 0.25 1" mesh="meshes__right_middle_2" />
                    <geom pos="0.0090859 0.040963 0.0061003" quat="0.694854 0.13106 0.694856 -0.13106" type="mesh" rgba="0.25 0.25 0.25 1" mesh="meshes__right_middle_force_sensor_2" />
                    <geom pos="0.0098294 0.056051 0.0061006" quat="0.66729 -0.233926 0.667293 0.233927" type="mesh" rgba="0.25 0.25 0.25 1" mesh="meshes__right_middle_force_sensor_3" />
                  </body>
                </body>
                <body name="rh56e2_right_ring_1" pos="0.00453021 0.00056467 0.265843" quat="0.486731 0.512926 0.512926 0.486731">
                  <inertial pos="0.000970415 0.0101672 0.00864067" quat="0.546403 0.481534 -0.539503 0.422498" mass="0.0188928" diaginertia="3.95018e-06 3.76424e-06 1.19901e-06" />
                  <joint name="rh56e2_right_ring_1_joint" pos="0 0 0" axis="0 0 -1" range="0 1.4381" actuatorfrcrange="-1 1" />
                  <geom type="mesh" rgba="0.25 0.25 0.25 1" mesh="meshes__right_ring_1" />
                  <geom pos="0.012046 0.019649 0.006651" quat="0.704887 -0.0936618 0.700876 0.0559809" type="mesh" rgba="0.25 0.25 0.25 1" mesh="meshes__right_ring_force_sensor_1" />
                  <body name="rh56e2_right_ring_2" pos="0.0034259 0.032596 0.00055">
                    <inertial pos="-0.00133295 0.0162914 0.00895521" quat="0.52677 0.377578 -0.608846 0.457444" mass="0.0113437" diaginertia="3.21223e-06 3.01634e-06 5.31075e-07" />
                    <joint name="rh56e2_right_ring_2_joint" pos="0 0 0" axis="0 0 -1" range="0 1.47637" actuatorfrcrange="-1 1" />
                    <geom type="mesh" rgba="0.25 0.25 0.25 1" mesh="meshes__right_ring_2" />
                    <geom pos="0.0081655 0.037446 0.0060795" quat="0.692694 0.103257 0.699527 -0.142038" type="mesh" rgba="0.25 0.25 0.25 1" mesh="meshes__right_ring_force_sensor_2" />
                    <geom pos="0.0086237 0.052572 0.0060954" quat="0.6723 -0.264487 0.655779 0.219118" type="mesh" rgba="0.25 0.25 0.25 1" mesh="meshes__right_ring_force_sensor_3" />
                  </body>
                </body>
                <body name="rh56e2_right_little_1" pos="0.025916 0.000564669 0.262663" quat="0.473153 0.525477 0.525477 0.473153">
                  <inertial pos="0.000599155 0.00971112 0.00916498" quat="0.527401 0.506679 -0.540235 0.416258" mass="0.0188928" diaginertia="3.94629e-06 3.7633e-06 1.19717e-06" />
                  <joint name="rh56e2_right_little_1_joint" pos="0 0 0" axis="0 0 -1" range="0 1.4381" actuatorfrcrange="-1 1" />
                  <geom type="mesh" rgba="0.25 0.25 0.25 1" mesh="meshes__right_little_1" />
                  <geom pos="0.012046 0.019649 0.006651" quat="0.706132 -0.112374 0.69812 0.0371073" type="mesh" rgba="0.25 0.25 0.25 1" mesh="meshes__right_little_force_sensor_1" />
                  <body name="rh56e2_right_little_2" pos="0.0034259 0.032596 0.00055">
                    <inertial pos="-0.00148048 0.0158289 0.00973055" quat="0.472706 0.354855 -0.648081 0.480227" mass="0.0120013" diaginertia="2.93409e-06 2.85029e-06 4.70358e-07" />
                    <joint name="rh56e2_right_little_2_joint" pos="0 0 0" axis="0 0 -1" range="0 1.47637" actuatorfrcrange="-1 1" />
                    <geom type="mesh" rgba="0.25 0.25 0.25 1" mesh="meshes__right_little_2" />
                    <geom pos="0.0064512 0.027683 0.0061172" quat="0.689046 0.0814204 0.702404 -0.158792" type="mesh" rgba="0.25 0.25 0.25 1" mesh="meshes__right_little_force_sensor_2" />
                    <geom pos="0.0063972 0.042707 0.0061154" quat="0.678772 -0.289133 0.645293 0.198161" type="mesh" rgba="0.25 0.25 0.25 1" mesh="meshes__right_little_force_sensor_3" />
                  </body>
                </body>
              </body>
            </body>
          </body>
        </body>
      </body>
    </body>
    <geom name="floor" type="plane" pos="0 0 0" size="3 3 0.1" rgba="0.90 0.92 0.95 1" condim="3" friction="1.0 0.02 0.002" />
    <geom name="robot_pedestal" type="box" pos="0.55 0 0.26" size="0.12 0.12 0.26" rgba="0.22 0.24 0.28 1" />
    <light name="key_light" pos="1.8 -1.4 2.6" dir="-0.4 0.3 -1" diffuse="0.95 0.95 0.95" specular="0.2 0.2 0.2" castshadow="true" />
    <light name="fill_light" pos="-0.8 1.2 2.0" dir="0.2 -0.2 -1" diffuse="0.45 0.45 0.45" specular="0.05 0.05 0.05" castshadow="false" />
  </worldbody>
  <option timestep="0.002" gravity="0 0 -9.81" integrator="implicitfast" iterations="50" cone="elliptic" />
  <visual>
    <global offwidth="1600" offheight="1200" />
  </visual>
  <equality>
    <joint name="rh56e2_right_thumb_3_joint_mimic" joint1="rh56e2_right_thumb_3_joint" joint2="rh56e2_right_thumb_2_joint" polycoef="0 0.8392 0 0 0" />
    <joint name="rh56e2_right_thumb_4_joint_mimic" joint1="rh56e2_right_thumb_4_joint" joint2="rh56e2_right_thumb_3_joint" polycoef="0 0.891 0 0 0" />
    <joint name="rh56e2_right_index_2_joint_mimic" joint1="rh56e2_right_index_2_joint" joint2="rh56e2_right_index_1_joint" polycoef="0 1.0843 0 0 0" />
    <joint name="rh56e2_right_middle_2_joint_mimic" joint1="rh56e2_right_middle_2_joint" joint2="rh56e2_right_middle_1_joint" polycoef="0 1.0843 0 0 0" />
    <joint name="rh56e2_right_ring_2_joint_mimic" joint1="rh56e2_right_ring_2_joint" joint2="rh56e2_right_ring_1_joint" polycoef="0 1.0843 0 0 0" />
    <joint name="rh56e2_right_little_2_joint_mimic" joint1="rh56e2_right_little_2_joint" joint2="rh56e2_right_little_1_joint" polycoef="0 1.0843 0 0 0" />
  </equality>
  <actuator>
    <position name="j1_act" joint="j1" kp="200" ctrllimited="true" ctrlrange="-3.0543 3.0543" />
    <position name="j2_act" joint="j2" kp="200" ctrllimited="true" ctrlrange="-4.6251 1.4835" />
    <position name="j3_act" joint="j3" kp="200" ctrllimited="true" ctrlrange="-2.8274 2.8274" />
    <position name="j4_act" joint="j4" kp="200" ctrllimited="true" ctrlrange="-4.6251 1.4835" />
    <position name="j5_act" joint="j5" kp="200" ctrllimited="true" ctrlrange="-3.0543 3.0543" />
    <position name="j6_act" joint="j6" kp="200" ctrllimited="true" ctrlrange="-3.0543 3.0543" />
    <position name="rh56e2_right_thumb_1_joint_act" joint="rh56e2_right_thumb_1_joint" kp="25" ctrllimited="true" ctrlrange="0 1.658" />
    <position name="rh56e2_right_thumb_2_joint_act" joint="rh56e2_right_thumb_2_joint" kp="25" ctrllimited="true" ctrlrange="0 0.62" />
    <position name="rh56e2_right_index_1_joint_act" joint="rh56e2_right_index_1_joint" kp="25" ctrllimited="true" ctrlrange="0 1.4381" />
    <position name="rh56e2_right_middle_1_joint_act" joint="rh56e2_right_middle_1_joint" kp="25" ctrllimited="true" ctrlrange="0 1.4381" />
    <position name="rh56e2_right_ring_1_joint_act" joint="rh56e2_right_ring_1_joint" kp="25" ctrllimited="true" ctrlrange="0 1.4381" />
    <position name="rh56e2_right_little_1_joint_act" joint="rh56e2_right_little_1_joint" kp="25" ctrllimited="true" ctrlrange="0 1.4381" />
  </actuator>
  <keyframe>
    <key name="home" qpos="-1.5707963 -1.5707963 -1.5707963 -1.5707963 1.5707963 0 0 0 0 0 0 0 0 0 0 0 0 0" ctrl="-1.5707963 -1.5707963 -1.5707963 -1.5707963 1.5707963 0 0 0 0 0 0 0" />
  </keyframe>
</mujoco>